try { print("In try block"); throw "Test exception"; } catch (error) { print("Caught: " + error); }
