function testException() { try { let x = 10 / 0; } catch (error) { print("Caught: " + error); } } testException();
